<?xml version='1.0' encoding='UTF-8'?>
<rss version="2.0"><channel><title>Cronfed on wenli</title><description>Fresh cron output from cronfed</description><link>http://hatnote.com</link><ttl>30</ttl><generator>cronfed v1.0</generator><lastBuildDate>Sun, 29 Mar 2020 08:30:01 +0000</lastBuildDate><item><title>Cron: &lt;hatnote@wenli&gt; $PYTHON_BIN -m cronfed --save 1024 --link http://hatnote.com --output $CRON_RSS_PATH $HATNOTE_MAIL_PATH 2&gt;&amp;1 | tee -a $LOG_BASE_PATH/cronfed.txt</title><description>At Sun, 29 Mar 2020 04:30:02 +0000 (UTC), Cron ran:

	$PYTHON_BIN -m cronfed --save 1024 --link http://hatnote.com --output $CRON_RSS_PATH $HATNOTE_MAIL_PATH 2&gt;&amp;1 | tee -a $LOG_BASE_PATH/cronfed.txt

Python exception: IOError.

Command output:

	Tracebac... (1086 bytes) ...atnote'
</description><link>http://hatnote.com</link><pubDate>Sun, 29 Mar 2020 04:30:02 +0000 (UTC)</pubDate><guid>http://hatnote.com/20200329043002.136C5BC78A</guid></item></channel></rss>